<!DOCTYPE html>
<html lang="en">
<head>
	<meta charset="UTF-8">
	<title>Document</title>
</head>
<body>
	
</body>
<script>
	/*function fn(){
		await 'hi';
	}*/ //await is only valid in async function

	//1.await只能放到async函数体中,一般async要和await配合使用
	/*async function fn(){
		let data1 = await 5+5;
		return data1;
		// return 111;
		//2.await表示后面的处理需要等待，如果后面不是异步的promise，直接返回对应的值。async函数内部return语句返回的值，会成为then方法回调函数的参数,如果没有return，则参数为undefined
	}
	console.log(fn());
	fn()
	.then(data=>{
		console.log(data);
	})
	.catch(err=>{
		console.log(err);
	})
	.finally(()=>{
		console.log('finally...');
	})*/


	// async函数内部抛出错误，会导致返回的 Promise 对象变为reject状态。抛出的错误对象会被catch方法回调函数接收到。
	/*async function f() {
	  throw new Error('出错了');
	}
	f().then(
	  v => console.log(v),// Error: 出错了
	  e => console.log(e)
	)*/
	
	

	//3.await表示后面的处理需要等待,通常await后面是一个 Promise 对象，返回该对象的结果
	let promise = new Promise((resolve,reject)=>{
		setTimeout(()=>{
			resolve('hello');
		},1000)		
	})

	/*async function fn2(){
		let data2 = await promise;
		console.log(data2);
	}
	fn2();*/

	/*async function fn3(){
		// await命令后面的 Promise 对象如果变为reject状态，程序中止,reject的参数会被catch方法的回调函数接收到。
		await Promise.reject('出错了！');
		let data3 = await promise;
		//因为promise的状态变为reject，所以不会执行console.log(data3);
		console.log(data3);
	}
	fn3()
	.then(data=>{
		console.log(data);
	})
	.catch(err=>{
		console.log(err);
	})*/

	// 有时，我们希望即使前一个异步操作失败，也不要中断后面的异步操作。这时可以将第一个await放在try...catch结构里面，这样不管这个异步操作是否成功，第二个await都会执行。
	//防止出错的方法，是await语句放在try...catch代码块之中。
	/*async function fn4(){
		try{
			// 如果有多个await命令，可以统一放在try...catch结构中。
			await Promise.reject('出错了');

		}
		catch(err){
			console.log(err);
		}
		return await Promise.resolve('hello');

		// 另一种写法
		// await Promise.reject('出错了')
		// .catch(err => console.log(err));

		// await Promise.resolve('hello')
	}
	fn4()
	.then(data => {console.log(data)})
	.catch(err => {console.log(err)});*/


	// async函数返回的 Promise 对象，必须等到内部所有await命令后面的 Promise 对象执行完，才会发生状态改变，除非遇到return语句或者抛出错误。也就是说，只有async函数内部的异步操作执行完，才会执行then方法指定的回调函数。
	/*async function f2(){
		await new Promise((resolve,reject)=>{
			resolve('1');
			console.log('1');
		})
		await new Promise((resolve,reject)=>{
			 // throw new Error('出错了');
			resolve('2');
			console.log('2');
		})
		return 4;
		await new Promise((resolve,reject)=>{
			resolve('3');
			console.log('3');
		})
	}
	f2()
	.then(data => console.log(data))
	.catch(err => console.log(err));*/


	/*async function f5() {
	  // return await Promise.reject('出错了');
	  await Promise.reject('出错了');
	}
	f5()
	.then(v => console.log(v))
	.catch(e => console.log(e))*/
	// 出错了
	// 注意，上面代码中，await语句前面没有return，但是reject方法的参数依然传入了catch方法的回调函数。这里如果在await前面加上return，效果是一样的。



</script>
</html>